2025-02-13T15:18:02 {"cpu": 0.19287109375, "cpu_total": 8, "cpu_usage": 0.02410888671875, "memory": 1804.0, "memory_total": 4840.0, "memory_usage": 0.37272727272727274, "pipeline_run_id": 44, "pipeline_schedule_id": 2, "pipeline_uuid": "datos_ventas", "hostname": "4dc745957cf6", "level": "INFO", "message": "Pipeline datos_ventas for run 44 in schedule 2 is alive.", "timestamp": 1739459882.722, "uuid": "76ccd39c3b264b2390b7c58bb1b17fb7"}
2025-02-13T15:18:02 {"cpu": 0.19287109375, "cpu_total": 8, "cpu_usage": 0.02410888671875, "memory": 1809.0, "memory_total": 4840.0, "memory_usage": 0.3737603305785124, "pipeline_run_id": 44, "pipeline_schedule_id": 2, "pipeline_uuid": "datos_ventas", "hostname": "4dc745957cf6", "level": "INFO", "message": "Pipeline datos_ventas for run 44 in schedule 2 is alive.", "timestamp": 1739459882.870193, "uuid": "2ba9f236b0ec403c97f8d83500d94820"}
2025-02-13T15:18:02 {"block_run_id": 173, "block_uuid": "postgres_tables_creation", "pipeline_run_id": 44, "pipeline_schedule_id": 2, "pipeline_uuid": "datos_ventas", "hostname": "4dc745957cf6", "level": "INFO", "message": "Execute PipelineRun 44, BlockRun 173: pipeline datos_ventas block postgres_tables_creation", "timestamp": 1739459882.935136, "uuid": "8014284927374969973590947f559531"}
2025-02-13T15:18:03 {"block_run_id": 173, "block_uuid": "postgres_tables_creation", "pipeline_run_id": 44, "pipeline_schedule_id": 2, "pipeline_uuid": "datos_ventas", "hostname": "4dc745957cf6", "level": "INFO", "message": "BlockRun 173 (block_uuid: postgres_tables_creation) completes.", "timestamp": 1739459883.12683, "uuid": "27541f90df554471a9ad04aa794ede60"}
2025-02-13T15:18:11 {"cpu": 0.18994140625, "cpu_total": 8, "cpu_usage": 0.02374267578125, "memory": 1802.0, "memory_total": 4840.0, "memory_usage": 0.3723140495867769, "pipeline_run_id": 44, "pipeline_schedule_id": 2, "pipeline_uuid": "datos_ventas", "hostname": "4dc745957cf6", "level": "INFO", "message": "Pipeline datos_ventas for run 44 in schedule 2 is alive.", "timestamp": 1739459891.758698, "uuid": "c03dc087eb274784a54b25068ac05dd3"}
2025-02-13T15:18:11 {"block_run_id": 174, "block_uuid": "postgres_data_insertion", "pipeline_run_id": 44, "pipeline_schedule_id": 2, "pipeline_uuid": "datos_ventas", "hostname": "4dc745957cf6", "level": "INFO", "message": "Execute PipelineRun 44, BlockRun 174: pipeline datos_ventas block postgres_data_insertion", "timestamp": 1739459891.901415, "uuid": "c6ce2333e2fa43f4826661f9e12f4ec4"}
2025-02-13T15:18:12 {"block_run_id": 174, "block_uuid": "postgres_data_insertion", "pipeline_run_id": 44, "pipeline_schedule_id": 2, "pipeline_uuid": "datos_ventas", "hostname": "4dc745957cf6", "level": "INFO", "message": "BlockRun 174 (block_uuid: postgres_data_insertion) completes.", "timestamp": 1739459892.206283, "uuid": "ab98f26db1634a88a8268d85b40e018f"}
2025-02-13T15:18:21 {"cpu": 0.1982421875, "cpu_total": 8, "cpu_usage": 0.0247802734375, "memory": 1795.0, "memory_total": 4840.0, "memory_usage": 0.37086776859504134, "pipeline_run_id": 44, "pipeline_schedule_id": 2, "pipeline_uuid": "datos_ventas", "hostname": "4dc745957cf6", "level": "INFO", "message": "Pipeline datos_ventas for run 44 in schedule 2 is alive.", "timestamp": 1739459901.883073, "uuid": "887f2c1ba35e42eda74a8bca559d86f1"}
2025-02-13T15:18:22 {"block_run_id": 175, "block_uuid": "postgres_data_transformation", "pipeline_run_id": 44, "pipeline_schedule_id": 2, "pipeline_uuid": "datos_ventas", "hostname": "4dc745957cf6", "level": "INFO", "message": "Execute PipelineRun 44, BlockRun 175: pipeline datos_ventas block postgres_data_transformation", "timestamp": 1739459902.080239, "uuid": "b2c62fae73c94d1595caa6d6347bf07b"}
2025-02-13T15:18:22 {"block_run_id": 175, "block_uuid": "postgres_data_transformation", "pipeline_run_id": 44, "pipeline_schedule_id": 2, "pipeline_uuid": "datos_ventas", "hostname": "4dc745957cf6", "level": "INFO", "message": "BlockRun 175 (block_uuid: postgres_data_transformation) completes.", "timestamp": 1739459902.457512, "uuid": "d68698708a954530be01480b298cb7c2"}
2025-02-13T15:18:32 {"cpu": 0.1953125, "cpu_total": 8, "cpu_usage": 0.0244140625, "memory": 1793.0, "memory_total": 4840.0, "memory_usage": 0.3704545454545455, "pipeline_run_id": 44, "pipeline_schedule_id": 2, "pipeline_uuid": "datos_ventas", "hostname": "4dc745957cf6", "level": "INFO", "message": "Pipeline datos_ventas for run 44 in schedule 2 is alive.", "timestamp": 1739459912.033218, "uuid": "c9994f5a2e234aa0b96ec86211583ac1"}
2025-02-13T15:18:32 {"block_run_id": 176, "block_uuid": "postgres_data_exportation", "pipeline_run_id": 44, "pipeline_schedule_id": 2, "pipeline_uuid": "datos_ventas", "hostname": "4dc745957cf6", "level": "INFO", "message": "Execute PipelineRun 44, BlockRun 176: pipeline datos_ventas block postgres_data_exportation", "timestamp": 1739459912.160852, "uuid": "69d41bf03ecc4555b3d8fbabfbffbe40"}
2025-02-13T15:18:33 {"block_run_id": 176, "block_uuid": "postgres_data_exportation", "pipeline_run_id": 44, "pipeline_schedule_id": 2, "pipeline_uuid": "datos_ventas", "hostname": "4dc745957cf6", "level": "EXCEPTION", "message": "BlockRun 176 (block_uuid: postgres_data_exportation) failed.", "timestamp": 1739459913.329195, "uuid": "22d634f0a3d04dc4beaf2d0967f3e36d", "error": "Traceback (most recent call last):\n  File \"/usr/local/lib/python3.10/site-packages/mage_ai/data_preparation/executors/block_executor.py\", line 647, in execute\n    result = __execute_with_retry()\n  File \"/usr/local/lib/python3.10/site-packages/mage_ai/shared/retry.py\", line 54, in retry_func\n    raise e\n  File \"/usr/local/lib/python3.10/site-packages/mage_ai/shared/retry.py\", line 38, in retry_func\n    return func(*args, **kwargs)\n  File \"/usr/local/lib/python3.10/site-packages/mage_ai/data_preparation/executors/block_executor.py\", line 621, in __execute_with_retry\n    return self._execute(\n  File \"/usr/local/lib/python3.10/site-packages/mage_ai/data_preparation/executors/block_executor.py\", line 1154, in _execute\n    result = self.block.execute_sync(\n  File \"/usr/local/lib/python3.10/site-packages/mage_ai/data_preparation/models/block/__init__.py\", line 1691, in execute_sync\n    return __execute()\n  File \"/usr/local/lib/python3.10/site-packages/mage_ai/data_preparation/models/block/__init__.py\", line 1668, in __execute\n    raise err\n  File \"/usr/local/lib/python3.10/site-packages/mage_ai/data_preparation/models/block/__init__.py\", line 1570, in __execute\n    output = self.execute_block(\n  File \"/usr/local/lib/python3.10/site-packages/mage_ai/data_preparation/models/block/__init__.py\", line 1910, in execute_block\n    outputs = self._execute_block(\n  File \"/usr/local/lib/python3.10/site-packages/mage_ai/data_preparation/models/block/__init__.py\", line 2073, in _execute_block\n    outputs = self.execute_block_function(\n  File \"/usr/local/lib/python3.10/site-packages/mage_ai/data_preparation/models/block/__init__.py\", line 2169, in execute_block_function\n    output = block_function_updated(*input_vars, **global_vars)\n  File \"<string>\", line 22, in export_data_to_new_table\n  File \"/usr/local/lib/python3.10/site-packages/mage_ai/io/sql.py\", line 380, in export\n    __process()\n  File \"/usr/local/lib/python3.10/site-packages/mage_ai/io/sql.py\", line 360, in __process\n    self.upload_dataframe(\n  File \"/usr/local/lib/python3.10/site-packages/mage_ai/io/postgres.py\", line 412, in upload_dataframe\n    cursor.copy_expert(f\"\"\"\npsycopg2.errors.UniqueViolation: duplicate key value violates unique constraint \"detalle_ventas_pkey\"\nDETAIL:  Key (id)=(1) already exists.\nCONTEXT:  COPY detalle_ventas, line 1\n\n", "error_stack": ["  File \"/usr/local/bin/mage\", line 8, in <module>\n    sys.exit(app())\n", "  File \"/usr/local/lib/python3.10/site-packages/typer/main.py\", line 311, in __call__\n    return get_command(self)(*args, **kwargs)\n", "  File \"/usr/local/lib/python3.10/site-packages/click/core.py\", line 1161, in __call__\n    return self.main(*args, **kwargs)\n", "  File \"/usr/local/lib/python3.10/site-packages/typer/core.py\", line 778, in main\n    return _main(\n", "  File \"/usr/local/lib/python3.10/site-packages/typer/core.py\", line 216, in _main\n    rv = self.invoke(ctx)\n", "  File \"/usr/local/lib/python3.10/site-packages/click/core.py\", line 1697, in invoke\n    return _process_result(sub_ctx.command.invoke(sub_ctx))\n", "  File \"/usr/local/lib/python3.10/site-packages/click/core.py\", line 1443, in invoke\n    return ctx.invoke(self.callback, **ctx.params)\n", "  File \"/usr/local/lib/python3.10/site-packages/click/core.py\", line 788, in invoke\n    return __callback(*args, **kwargs)\n", "  File \"/usr/local/lib/python3.10/site-packages/typer/main.py\", line 683, in wrapper\n    return callback(**use_params)  # type: ignore\n", "  File \"/usr/local/lib/python3.10/site-packages/mage_ai/cli/main.py\", line 147, in start\n    start_server(\n", "  File \"/usr/local/lib/python3.10/site-packages/mage_ai/server/server.py\", line 809, in start_server\n    scheduler_manager.start_scheduler()\n", "  File \"/usr/local/lib/python3.10/site-packages/mage_ai/server/scheduler_manager.py\", line 106, in start_scheduler\n    proc.start()\n", "  File \"/usr/local/lib/python3.10/multiprocessing/process.py\", line 121, in start\n    self._popen = self._Popen(self)\n", "  File \"/usr/local/lib/python3.10/multiprocessing/context.py\", line 224, in _Popen\n    return _default_context.get_context().Process._Popen(process_obj)\n", "  File \"/usr/local/lib/python3.10/multiprocessing/context.py\", line 281, in _Popen\n    return Popen(process_obj)\n", "  File \"/usr/local/lib/python3.10/multiprocessing/popen_fork.py\", line 19, in __init__\n    self._launch(process_obj)\n", "  File \"/usr/local/lib/python3.10/multiprocessing/popen_fork.py\", line 71, in _launch\n    code = process_obj._bootstrap(parent_sentinel=child_r)\n", "  File \"/usr/local/lib/python3.10/multiprocessing/process.py\", line 314, in _bootstrap\n    self.run()\n", "  File \"/usr/local/lib/python3.10/multiprocessing/process.py\", line 108, in run\n    self._target(*self._args, **self._kwargs)\n", "  File \"/usr/local/lib/python3.10/site-packages/mage_ai/orchestration/db/process.py\", line 15, in start_session_and_run\n    results = target(*args)\n", "  File \"/usr/local/lib/python3.10/site-packages/mage_ai/server/scheduler_manager.py\", line 58, in run_scheduler\n    LoopTimeTrigger().start()\n", "  File \"/usr/local/lib/python3.10/site-packages/mage_ai/orchestration/triggers/loop_time_trigger.py\", line 14, in start\n    self.run()\n", "  File \"/usr/local/lib/python3.10/site-packages/mage_ai/orchestration/triggers/time_trigger.py\", line 11, in run\n    schedule_all()\n", "  File \"/usr/local/lib/python3.10/site-packages/mage_ai/orchestration/pipeline_scheduler_original.py\", line 1730, in schedule_all\n    PipelineScheduler(r).schedule()\n", "  File \"/usr/local/lib/python3.10/site-packages/mage_ai/orchestration/db/__init__.py\", line 159, in func_with_rollback\n    return func(*args, **kwargs)\n", "  File \"/usr/local/lib/python3.10/site-packages/mage_ai/orchestration/pipeline_scheduler_original.py\", line 333, in schedule\n    self.__schedule_blocks(block_runs)\n", "  File \"/usr/local/lib/python3.10/site-packages/mage_ai/orchestration/pipeline_scheduler_original.py\", line 640, in __schedule_blocks\n    job_manager.add_job(\n", "  File \"/usr/local/lib/python3.10/site-packages/mage_ai/orchestration/job_manager.py\", line 20, in add_job\n    self.queue.enqueue(job_id, target, *args, **kwargs)\n", "  File \"/usr/local/lib/python3.10/site-packages/mage_ai/orchestration/queue/process_queue.py\", line 121, in enqueue\n    self.start_worker_pool()\n", "  File \"/usr/local/lib/python3.10/site-packages/mage_ai/orchestration/queue/process_queue.py\", line 198, in start_worker_pool\n    self.worker_pool_proc.start()\n", "  File \"/usr/local/lib/python3.10/multiprocessing/process.py\", line 121, in start\n    self._popen = self._Popen(self)\n", "  File \"/usr/local/lib/python3.10/multiprocessing/context.py\", line 224, in _Popen\n    return _default_context.get_context().Process._Popen(process_obj)\n", "  File \"/usr/local/lib/python3.10/multiprocessing/context.py\", line 281, in _Popen\n    return Popen(process_obj)\n", "  File \"/usr/local/lib/python3.10/multiprocessing/popen_fork.py\", line 19, in __init__\n    self._launch(process_obj)\n", "  File \"/usr/local/lib/python3.10/multiprocessing/popen_fork.py\", line 71, in _launch\n    code = process_obj._bootstrap(parent_sentinel=child_r)\n", "  File \"/usr/local/lib/python3.10/multiprocessing/process.py\", line 314, in _bootstrap\n    self.run()\n", "  File \"/usr/local/lib/python3.10/multiprocessing/process.py\", line 108, in run\n    self._target(*self._args, **self._kwargs)\n", "  File \"/usr/local/lib/python3.10/site-packages/mage_ai/orchestration/queue/process_queue.py\", line 351, in poll_job_and_execute\n    worker.start()\n", "  File \"/usr/local/lib/python3.10/multiprocessing/process.py\", line 121, in start\n    self._popen = self._Popen(self)\n", "  File \"/usr/local/lib/python3.10/multiprocessing/context.py\", line 224, in _Popen\n    return _default_context.get_context().Process._Popen(process_obj)\n", "  File \"/usr/local/lib/python3.10/multiprocessing/context.py\", line 281, in _Popen\n    return Popen(process_obj)\n", "  File \"/usr/local/lib/python3.10/multiprocessing/popen_fork.py\", line 19, in __init__\n    self._launch(process_obj)\n", "  File \"/usr/local/lib/python3.10/multiprocessing/popen_fork.py\", line 71, in _launch\n    code = process_obj._bootstrap(parent_sentinel=child_r)\n", "  File \"/usr/local/lib/python3.10/multiprocessing/process.py\", line 314, in _bootstrap\n    self.run()\n", "  File \"/usr/local/lib/python3.10/site-packages/newrelic/api/background_task.py\", line 117, in wrapper\n    return wrapped(*args, **kwargs)\n", "  File \"/usr/local/lib/python3.10/site-packages/mage_ai/orchestration/queue/process_queue.py\", line 315, in run\n    start_session_and_run(args[1], *args[2], **args[3])\n", "  File \"/usr/local/lib/python3.10/site-packages/mage_ai/orchestration/db/process.py\", line 15, in start_session_and_run\n    results = target(*args)\n", "  File \"/usr/local/lib/python3.10/site-packages/mage_ai/orchestration/pipeline_scheduler_original.py\", line 1235, in run_block\n    return ExecutorFactory.get_block_executor(\n", "  File \"/usr/local/lib/python3.10/site-packages/mage_ai/data_preparation/executors/block_executor.py\", line 682, in execute\n    on_failure(\n", "  File \"/usr/local/lib/python3.10/site-packages/mage_ai/orchestration/db/__init__.py\", line 159, in func_with_rollback\n    return func(*args, **kwargs)\n", "  File \"/usr/local/lib/python3.10/site-packages/mage_ai/orchestration/pipeline_scheduler_original.py\", line 464, in on_block_failure\n    self.logger.exception(\n", "  File \"/usr/local/lib/python3.10/site-packages/mage_ai/data_preparation/logging/logger.py\", line 30, in exception\n    self.__send_message('exception', message, **kwargs)\n", "  File \"/usr/local/lib/python3.10/site-packages/mage_ai/data_preparation/logging/logger.py\", line 65, in __send_message\n    data['error_stack'] = traceback.format_stack()\n"], "error_stacktrace": "duplicate key value violates unique constraint \"detalle_ventas_pkey\"\nDETAIL:  Key (id)=(1) already exists.\nCONTEXT:  COPY detalle_ventas, line 1\n"}
Traceback (most recent call last):
  File "/usr/local/lib/python3.10/site-packages/mage_ai/data_preparation/executors/block_executor.py", line 647, in execute
    result = __execute_with_retry()
  File "/usr/local/lib/python3.10/site-packages/mage_ai/shared/retry.py", line 54, in retry_func
    raise e
  File "/usr/local/lib/python3.10/site-packages/mage_ai/shared/retry.py", line 38, in retry_func
    return func(*args, **kwargs)
  File "/usr/local/lib/python3.10/site-packages/mage_ai/data_preparation/executors/block_executor.py", line 621, in __execute_with_retry
    return self._execute(
  File "/usr/local/lib/python3.10/site-packages/mage_ai/data_preparation/executors/block_executor.py", line 1154, in _execute
    result = self.block.execute_sync(
  File "/usr/local/lib/python3.10/site-packages/mage_ai/data_preparation/models/block/__init__.py", line 1691, in execute_sync
    return __execute()
  File "/usr/local/lib/python3.10/site-packages/mage_ai/data_preparation/models/block/__init__.py", line 1668, in __execute
    raise err
  File "/usr/local/lib/python3.10/site-packages/mage_ai/data_preparation/models/block/__init__.py", line 1570, in __execute
    output = self.execute_block(
  File "/usr/local/lib/python3.10/site-packages/mage_ai/data_preparation/models/block/__init__.py", line 1910, in execute_block
    outputs = self._execute_block(
  File "/usr/local/lib/python3.10/site-packages/mage_ai/data_preparation/models/block/__init__.py", line 2073, in _execute_block
    outputs = self.execute_block_function(
  File "/usr/local/lib/python3.10/site-packages/mage_ai/data_preparation/models/block/__init__.py", line 2169, in execute_block_function
    output = block_function_updated(*input_vars, **global_vars)
  File "<string>", line 22, in export_data_to_new_table
  File "/usr/local/lib/python3.10/site-packages/mage_ai/io/sql.py", line 380, in export
    __process()
  File "/usr/local/lib/python3.10/site-packages/mage_ai/io/sql.py", line 360, in __process
    self.upload_dataframe(
  File "/usr/local/lib/python3.10/site-packages/mage_ai/io/postgres.py", line 412, in upload_dataframe
    cursor.copy_expert(f"""
psycopg2.errors.UniqueViolation: duplicate key value violates unique constraint "detalle_ventas_pkey"
DETAIL:  Key (id)=(1) already exists.
CONTEXT:  COPY detalle_ventas, line 1

2025-02-13T15:18:39 {"cpu": 0.20361328125, "cpu_total": 8, "cpu_usage": 0.02545166015625, "memory": 1798.0, "memory_total": 4840.0, "memory_usage": 0.3714876033057851, "pipeline_run_id": 44, "pipeline_schedule_id": 2, "pipeline_uuid": "datos_ventas", "hostname": "4dc745957cf6", "level": "INFO", "message": "Pipeline datos_ventas for run 44 in schedule 2 is alive.", "timestamp": 1739459919.95598, "uuid": "c66fdf2896664a8984859c8e70ffc62b"}
