2025-02-13T15:10:09 {"cpu": 0.173828125, "cpu_total": 8, "cpu_usage": 0.021728515625, "memory": 1521.0, "memory_total": 4840.0, "memory_usage": 0.31425619834710744, "pipeline_run_id": 36, "pipeline_schedule_id": 2, "pipeline_uuid": "datos_ventas", "hostname": "4dc745957cf6", "level": "INFO", "message": "Pipeline datos_ventas for run 36 in schedule 2 is alive.", "timestamp": 1739459409.603682, "uuid": "28e0306e53c14dfca6506e63a884a66a"}
2025-02-13T15:10:09 {"cpu": 0.173828125, "cpu_total": 8, "cpu_usage": 0.021728515625, "memory": 1533.0, "memory_total": 4840.0, "memory_usage": 0.3167355371900826, "pipeline_run_id": 36, "pipeline_schedule_id": 2, "pipeline_uuid": "datos_ventas", "hostname": "4dc745957cf6", "level": "INFO", "message": "Pipeline datos_ventas for run 36 in schedule 2 is alive.", "timestamp": 1739459409.660262, "uuid": "ac3e5982407f4c9084b275db5909a7a5"}
2025-02-13T15:10:09 {"block_run_id": 141, "block_uuid": "postgres_tables_creation", "pipeline_run_id": 36, "pipeline_schedule_id": 2, "pipeline_uuid": "datos_ventas", "hostname": "4dc745957cf6", "level": "INFO", "message": "Execute PipelineRun 36, BlockRun 141: pipeline datos_ventas block postgres_tables_creation", "timestamp": 1739459409.706688, "uuid": "cb10e31bdddf46fa9cb6ff54cdfc63ff"}
2025-02-13T15:10:09 {"block_run_id": 141, "block_uuid": "postgres_tables_creation", "pipeline_run_id": 36, "pipeline_schedule_id": 2, "pipeline_uuid": "datos_ventas", "hostname": "4dc745957cf6", "level": "INFO", "message": "BlockRun 141 (block_uuid: postgres_tables_creation) completes.", "timestamp": 1739459409.978544, "uuid": "95cefc2ecb324e9fb827535d703e1f55"}
2025-02-13T15:10:18 {"cpu": 0.171875, "cpu_total": 8, "cpu_usage": 0.021484375, "memory": 1507.0, "memory_total": 4840.0, "memory_usage": 0.31136363636363634, "pipeline_run_id": 36, "pipeline_schedule_id": 2, "pipeline_uuid": "datos_ventas", "hostname": "4dc745957cf6", "level": "INFO", "message": "Pipeline datos_ventas for run 36 in schedule 2 is alive.", "timestamp": 1739459418.568818, "uuid": "fd6e74fda60b4725a3ffa9789e93448e"}
2025-02-13T15:10:18 {"block_run_id": 142, "block_uuid": "postgres_data_insertion", "pipeline_run_id": 36, "pipeline_schedule_id": 2, "pipeline_uuid": "datos_ventas", "hostname": "4dc745957cf6", "level": "INFO", "message": "Execute PipelineRun 36, BlockRun 142: pipeline datos_ventas block postgres_data_insertion", "timestamp": 1739459418.67462, "uuid": "9a15e8e40b30408a9fc135efdd326e21"}
2025-02-13T15:10:18 {"block_run_id": 142, "block_uuid": "postgres_data_insertion", "pipeline_run_id": 36, "pipeline_schedule_id": 2, "pipeline_uuid": "datos_ventas", "hostname": "4dc745957cf6", "level": "INFO", "message": "BlockRun 142 (block_uuid: postgres_data_insertion) completes.", "timestamp": 1739459418.898388, "uuid": "423a3c4870bf4e23ab46741d25278a2d"}
2025-02-13T15:10:28 {"cpu": 0.17578125, "cpu_total": 8, "cpu_usage": 0.02197265625, "memory": 1526.0, "memory_total": 4840.0, "memory_usage": 0.31528925619834713, "pipeline_run_id": 36, "pipeline_schedule_id": 2, "pipeline_uuid": "datos_ventas", "hostname": "4dc745957cf6", "level": "INFO", "message": "Pipeline datos_ventas for run 36 in schedule 2 is alive.", "timestamp": 1739459428.672926, "uuid": "d38ec81e3b5f4edca0efc17cf955d95b"}
2025-02-13T15:10:28 {"block_run_id": 143, "block_uuid": "postgres_data_transformation", "pipeline_run_id": 36, "pipeline_schedule_id": 2, "pipeline_uuid": "datos_ventas", "hostname": "4dc745957cf6", "level": "INFO", "message": "Execute PipelineRun 36, BlockRun 143: pipeline datos_ventas block postgres_data_transformation", "timestamp": 1739459428.974509, "uuid": "2abf420261a9408a89d12fe21f097eb2"}
2025-02-13T15:10:29 {"block_run_id": 143, "block_uuid": "postgres_data_transformation", "pipeline_run_id": 36, "pipeline_schedule_id": 2, "pipeline_uuid": "datos_ventas", "hostname": "4dc745957cf6", "level": "INFO", "message": "BlockRun 143 (block_uuid: postgres_data_transformation) completes.", "timestamp": 1739459429.336201, "uuid": "ba64eb4a925c47878fd5d79d7a7beda0"}
2025-02-13T15:10:38 {"cpu": 0.173828125, "cpu_total": 8, "cpu_usage": 0.021728515625, "memory": 1522.0, "memory_total": 4840.0, "memory_usage": 0.31446280991735537, "pipeline_run_id": 36, "pipeline_schedule_id": 2, "pipeline_uuid": "datos_ventas", "hostname": "4dc745957cf6", "level": "INFO", "message": "Pipeline datos_ventas for run 36 in schedule 2 is alive.", "timestamp": 1739459438.797319, "uuid": "b5bcc8e114684951a5918377cb693aff"}
2025-02-13T15:10:38 {"block_run_id": 144, "block_uuid": "postgres_data_exportation", "pipeline_run_id": 36, "pipeline_schedule_id": 2, "pipeline_uuid": "datos_ventas", "hostname": "4dc745957cf6", "level": "INFO", "message": "Execute PipelineRun 36, BlockRun 144: pipeline datos_ventas block postgres_data_exportation", "timestamp": 1739459438.974486, "uuid": "e6578999bcf24a63880d447567e2f59e"}
2025-02-13T15:10:40 {"block_run_id": 144, "block_uuid": "postgres_data_exportation", "pipeline_run_id": 36, "pipeline_schedule_id": 2, "pipeline_uuid": "datos_ventas", "hostname": "4dc745957cf6", "level": "EXCEPTION", "message": "BlockRun 144 (block_uuid: postgres_data_exportation) failed.", "timestamp": 1739459440.455469, "uuid": "f508ca75c5e94641a435bebafed32211", "error": "Traceback (most recent call last):\n  File \"/usr/local/lib/python3.10/site-packages/mage_ai/data_preparation/executors/block_executor.py\", line 647, in execute\n    result = __execute_with_retry()\n  File \"/usr/local/lib/python3.10/site-packages/mage_ai/shared/retry.py\", line 54, in retry_func\n    raise e\n  File \"/usr/local/lib/python3.10/site-packages/mage_ai/shared/retry.py\", line 38, in retry_func\n    return func(*args, **kwargs)\n  File \"/usr/local/lib/python3.10/site-packages/mage_ai/data_preparation/executors/block_executor.py\", line 621, in __execute_with_retry\n    return self._execute(\n  File \"/usr/local/lib/python3.10/site-packages/mage_ai/data_preparation/executors/block_executor.py\", line 1154, in _execute\n    result = self.block.execute_sync(\n  File \"/usr/local/lib/python3.10/site-packages/mage_ai/data_preparation/models/block/__init__.py\", line 1691, in execute_sync\n    return __execute()\n  File \"/usr/local/lib/python3.10/site-packages/mage_ai/data_preparation/models/block/__init__.py\", line 1668, in __execute\n    raise err\n  File \"/usr/local/lib/python3.10/site-packages/mage_ai/data_preparation/models/block/__init__.py\", line 1570, in __execute\n    output = self.execute_block(\n  File \"/usr/local/lib/python3.10/site-packages/mage_ai/data_preparation/models/block/__init__.py\", line 1910, in execute_block\n    outputs = self._execute_block(\n  File \"/usr/local/lib/python3.10/site-packages/mage_ai/data_preparation/models/block/__init__.py\", line 2073, in _execute_block\n    outputs = self.execute_block_function(\n  File \"/usr/local/lib/python3.10/site-packages/mage_ai/data_preparation/models/block/__init__.py\", line 2169, in execute_block_function\n    output = block_function_updated(*input_vars, **global_vars)\n  File \"<string>\", line 22, in export_data_to_new_table\n  File \"/usr/local/lib/python3.10/site-packages/mage_ai/io/sql.py\", line 380, in export\n    __process()\n  File \"/usr/local/lib/python3.10/site-packages/mage_ai/io/sql.py\", line 360, in __process\n    self.upload_dataframe(\n  File \"/usr/local/lib/python3.10/site-packages/mage_ai/io/postgres.py\", line 412, in upload_dataframe\n    cursor.copy_expert(f\"\"\"\npsycopg2.errors.InvalidTextRepresentation: invalid input syntax for type integer: \"7.0\"\nCONTEXT:  COPY detalle_ventas, line 1, column cantidad: \"7.0\"\n\n", "error_stack": ["  File \"/usr/local/bin/mage\", line 8, in <module>\n    sys.exit(app())\n", "  File \"/usr/local/lib/python3.10/site-packages/typer/main.py\", line 311, in __call__\n    return get_command(self)(*args, **kwargs)\n", "  File \"/usr/local/lib/python3.10/site-packages/click/core.py\", line 1161, in __call__\n    return self.main(*args, **kwargs)\n", "  File \"/usr/local/lib/python3.10/site-packages/typer/core.py\", line 778, in main\n    return _main(\n", "  File \"/usr/local/lib/python3.10/site-packages/typer/core.py\", line 216, in _main\n    rv = self.invoke(ctx)\n", "  File \"/usr/local/lib/python3.10/site-packages/click/core.py\", line 1697, in invoke\n    return _process_result(sub_ctx.command.invoke(sub_ctx))\n", "  File \"/usr/local/lib/python3.10/site-packages/click/core.py\", line 1443, in invoke\n    return ctx.invoke(self.callback, **ctx.params)\n", "  File \"/usr/local/lib/python3.10/site-packages/click/core.py\", line 788, in invoke\n    return __callback(*args, **kwargs)\n", "  File \"/usr/local/lib/python3.10/site-packages/typer/main.py\", line 683, in wrapper\n    return callback(**use_params)  # type: ignore\n", "  File \"/usr/local/lib/python3.10/site-packages/mage_ai/cli/main.py\", line 147, in start\n    start_server(\n", "  File \"/usr/local/lib/python3.10/site-packages/mage_ai/server/server.py\", line 809, in start_server\n    scheduler_manager.start_scheduler()\n", "  File \"/usr/local/lib/python3.10/site-packages/mage_ai/server/scheduler_manager.py\", line 106, in start_scheduler\n    proc.start()\n", "  File \"/usr/local/lib/python3.10/multiprocessing/process.py\", line 121, in start\n    self._popen = self._Popen(self)\n", "  File \"/usr/local/lib/python3.10/multiprocessing/context.py\", line 224, in _Popen\n    return _default_context.get_context().Process._Popen(process_obj)\n", "  File \"/usr/local/lib/python3.10/multiprocessing/context.py\", line 281, in _Popen\n    return Popen(process_obj)\n", "  File \"/usr/local/lib/python3.10/multiprocessing/popen_fork.py\", line 19, in __init__\n    self._launch(process_obj)\n", "  File \"/usr/local/lib/python3.10/multiprocessing/popen_fork.py\", line 71, in _launch\n    code = process_obj._bootstrap(parent_sentinel=child_r)\n", "  File \"/usr/local/lib/python3.10/multiprocessing/process.py\", line 314, in _bootstrap\n    self.run()\n", "  File \"/usr/local/lib/python3.10/multiprocessing/process.py\", line 108, in run\n    self._target(*self._args, **self._kwargs)\n", "  File \"/usr/local/lib/python3.10/site-packages/mage_ai/orchestration/db/process.py\", line 15, in start_session_and_run\n    results = target(*args)\n", "  File \"/usr/local/lib/python3.10/site-packages/mage_ai/server/scheduler_manager.py\", line 58, in run_scheduler\n    LoopTimeTrigger().start()\n", "  File \"/usr/local/lib/python3.10/site-packages/mage_ai/orchestration/triggers/loop_time_trigger.py\", line 14, in start\n    self.run()\n", "  File \"/usr/local/lib/python3.10/site-packages/mage_ai/orchestration/triggers/time_trigger.py\", line 11, in run\n    schedule_all()\n", "  File \"/usr/local/lib/python3.10/site-packages/mage_ai/orchestration/pipeline_scheduler_original.py\", line 1730, in schedule_all\n    PipelineScheduler(r).schedule()\n", "  File \"/usr/local/lib/python3.10/site-packages/mage_ai/orchestration/db/__init__.py\", line 159, in func_with_rollback\n    return func(*args, **kwargs)\n", "  File \"/usr/local/lib/python3.10/site-packages/mage_ai/orchestration/pipeline_scheduler_original.py\", line 333, in schedule\n    self.__schedule_blocks(block_runs)\n", "  File \"/usr/local/lib/python3.10/site-packages/mage_ai/orchestration/pipeline_scheduler_original.py\", line 640, in __schedule_blocks\n    job_manager.add_job(\n", "  File \"/usr/local/lib/python3.10/site-packages/mage_ai/orchestration/job_manager.py\", line 20, in add_job\n    self.queue.enqueue(job_id, target, *args, **kwargs)\n", "  File \"/usr/local/lib/python3.10/site-packages/mage_ai/orchestration/queue/process_queue.py\", line 121, in enqueue\n    self.start_worker_pool()\n", "  File \"/usr/local/lib/python3.10/site-packages/mage_ai/orchestration/queue/process_queue.py\", line 198, in start_worker_pool\n    self.worker_pool_proc.start()\n", "  File \"/usr/local/lib/python3.10/multiprocessing/process.py\", line 121, in start\n    self._popen = self._Popen(self)\n", "  File \"/usr/local/lib/python3.10/multiprocessing/context.py\", line 224, in _Popen\n    return _default_context.get_context().Process._Popen(process_obj)\n", "  File \"/usr/local/lib/python3.10/multiprocessing/context.py\", line 281, in _Popen\n    return Popen(process_obj)\n", "  File \"/usr/local/lib/python3.10/multiprocessing/popen_fork.py\", line 19, in __init__\n    self._launch(process_obj)\n", "  File \"/usr/local/lib/python3.10/multiprocessing/popen_fork.py\", line 71, in _launch\n    code = process_obj._bootstrap(parent_sentinel=child_r)\n", "  File \"/usr/local/lib/python3.10/multiprocessing/process.py\", line 314, in _bootstrap\n    self.run()\n", "  File \"/usr/local/lib/python3.10/multiprocessing/process.py\", line 108, in run\n    self._target(*self._args, **self._kwargs)\n", "  File \"/usr/local/lib/python3.10/site-packages/mage_ai/orchestration/queue/process_queue.py\", line 351, in poll_job_and_execute\n    worker.start()\n", "  File \"/usr/local/lib/python3.10/multiprocessing/process.py\", line 121, in start\n    self._popen = self._Popen(self)\n", "  File \"/usr/local/lib/python3.10/multiprocessing/context.py\", line 224, in _Popen\n    return _default_context.get_context().Process._Popen(process_obj)\n", "  File \"/usr/local/lib/python3.10/multiprocessing/context.py\", line 281, in _Popen\n    return Popen(process_obj)\n", "  File \"/usr/local/lib/python3.10/multiprocessing/popen_fork.py\", line 19, in __init__\n    self._launch(process_obj)\n", "  File \"/usr/local/lib/python3.10/multiprocessing/popen_fork.py\", line 71, in _launch\n    code = process_obj._bootstrap(parent_sentinel=child_r)\n", "  File \"/usr/local/lib/python3.10/multiprocessing/process.py\", line 314, in _bootstrap\n    self.run()\n", "  File \"/usr/local/lib/python3.10/site-packages/newrelic/api/background_task.py\", line 117, in wrapper\n    return wrapped(*args, **kwargs)\n", "  File \"/usr/local/lib/python3.10/site-packages/mage_ai/orchestration/queue/process_queue.py\", line 315, in run\n    start_session_and_run(args[1], *args[2], **args[3])\n", "  File \"/usr/local/lib/python3.10/site-packages/mage_ai/orchestration/db/process.py\", line 15, in start_session_and_run\n    results = target(*args)\n", "  File \"/usr/local/lib/python3.10/site-packages/mage_ai/orchestration/pipeline_scheduler_original.py\", line 1235, in run_block\n    return ExecutorFactory.get_block_executor(\n", "  File \"/usr/local/lib/python3.10/site-packages/mage_ai/data_preparation/executors/block_executor.py\", line 682, in execute\n    on_failure(\n", "  File \"/usr/local/lib/python3.10/site-packages/mage_ai/orchestration/db/__init__.py\", line 159, in func_with_rollback\n    return func(*args, **kwargs)\n", "  File \"/usr/local/lib/python3.10/site-packages/mage_ai/orchestration/pipeline_scheduler_original.py\", line 464, in on_block_failure\n    self.logger.exception(\n", "  File \"/usr/local/lib/python3.10/site-packages/mage_ai/data_preparation/logging/logger.py\", line 30, in exception\n    self.__send_message('exception', message, **kwargs)\n", "  File \"/usr/local/lib/python3.10/site-packages/mage_ai/data_preparation/logging/logger.py\", line 65, in __send_message\n    data['error_stack'] = traceback.format_stack()\n"], "error_stacktrace": "invalid input syntax for type integer: \"7.0\"\nCONTEXT:  COPY detalle_ventas, line 1, column cantidad: \"7.0\"\n"}
Traceback (most recent call last):
  File "/usr/local/lib/python3.10/site-packages/mage_ai/data_preparation/executors/block_executor.py", line 647, in execute
    result = __execute_with_retry()
  File "/usr/local/lib/python3.10/site-packages/mage_ai/shared/retry.py", line 54, in retry_func
    raise e
  File "/usr/local/lib/python3.10/site-packages/mage_ai/shared/retry.py", line 38, in retry_func
    return func(*args, **kwargs)
  File "/usr/local/lib/python3.10/site-packages/mage_ai/data_preparation/executors/block_executor.py", line 621, in __execute_with_retry
    return self._execute(
  File "/usr/local/lib/python3.10/site-packages/mage_ai/data_preparation/executors/block_executor.py", line 1154, in _execute
    result = self.block.execute_sync(
  File "/usr/local/lib/python3.10/site-packages/mage_ai/data_preparation/models/block/__init__.py", line 1691, in execute_sync
    return __execute()
  File "/usr/local/lib/python3.10/site-packages/mage_ai/data_preparation/models/block/__init__.py", line 1668, in __execute
    raise err
  File "/usr/local/lib/python3.10/site-packages/mage_ai/data_preparation/models/block/__init__.py", line 1570, in __execute
    output = self.execute_block(
  File "/usr/local/lib/python3.10/site-packages/mage_ai/data_preparation/models/block/__init__.py", line 1910, in execute_block
    outputs = self._execute_block(
  File "/usr/local/lib/python3.10/site-packages/mage_ai/data_preparation/models/block/__init__.py", line 2073, in _execute_block
    outputs = self.execute_block_function(
  File "/usr/local/lib/python3.10/site-packages/mage_ai/data_preparation/models/block/__init__.py", line 2169, in execute_block_function
    output = block_function_updated(*input_vars, **global_vars)
  File "<string>", line 22, in export_data_to_new_table
  File "/usr/local/lib/python3.10/site-packages/mage_ai/io/sql.py", line 380, in export
    __process()
  File "/usr/local/lib/python3.10/site-packages/mage_ai/io/sql.py", line 360, in __process
    self.upload_dataframe(
  File "/usr/local/lib/python3.10/site-packages/mage_ai/io/postgres.py", line 412, in upload_dataframe
    cursor.copy_expert(f"""
psycopg2.errors.InvalidTextRepresentation: invalid input syntax for type integer: "7.0"
CONTEXT:  COPY detalle_ventas, line 1, column cantidad: "7.0"

2025-02-13T15:10:48 {"cpu": 0.171875, "cpu_total": 8, "cpu_usage": 0.021484375, "memory": 1525.0, "memory_total": 4840.0, "memory_usage": 0.31508264462809915, "pipeline_run_id": 36, "pipeline_schedule_id": 2, "pipeline_uuid": "datos_ventas", "hostname": "4dc745957cf6", "level": "INFO", "message": "Pipeline datos_ventas for run 36 in schedule 2 is alive.", "timestamp": 1739459448.997109, "uuid": "2bbeb4da88bd4fbe80651d34b352a52c"}
